<?xml version="1.0" encoding="utf-8"?>
<robot name="drawer">

  <link name="base_link">
    <inertial>
      <origin xyz="0.170762501727078 -0.35 0.131563760738117" rpy="0 0 0" />
      <mass value="13.33460961599" />
      <inertia ixx="1.15061115937014" ixy="-2.04729931403782E-16"
               ixz="0.00511983500697809" iyy="0.406567555775539"
               iyz="1.94842027610842E-17" izz="1.17764867637739" />
    </inertial>

    <visual>
      <origin xyz="0 0 0" rpy="0 0 0" />
      <geometry>
        <mesh filename="meshes/base_link.STL" />
      </geometry>
      <material name="brown">
        <color rgba="0.545 0.270 0.074 1.0"/>
      </material>
    </visual>

    <collision>
      <origin xyz="0 0 0" rpy="0 0 0" />
      <geometry>
        <mesh filename="meshes/base_link.STL" />
      </geometry>
    </collision>
  </link>

  <link name="link1">
    <inertial>
      <origin xyz="0.202240478511955 -0.349999898571107 0.0901810418976017" rpy="0 0 0" />
      <mass value="9.9706439379001" />
      <inertia ixx="0.623547679310975" ixy="-1.64996382534564E-07"
               ixz="-0.00257596309201247" iyy="0.285043962775198"
               iyz="-7.85158305747548E-08" izz="0.776947982394923" />
    </inertial>

    <visual>
      <origin xyz="0 0 0" rpy="0 0 0" />
      <geometry>
        <mesh filename="meshes/link1.STL" />
      </geometry>
      <material name="brown">
        <color rgba="0.545 0.270 0.074 1.0"/>
      </material>
    </visual>

    <collision>
      <origin xyz="0 0 0" rpy="0 0 0" />
      <geometry>
        <mesh filename="meshes/link1.STL" />
      </geometry>
    </collision>
  </link>

  <joint name="Joint" type="prismatic">
    <origin xyz="0.379999999999998 0 0.0199999999999975" rpy="0 0 0" />
    <parent link="base_link" />
    <child link="link1" />
    <axis xyz="-1 0 0" />
    <limit lower="0" upper="0.36" effort="100" velocity="0.15" />
    <dynamics damping="1" friction="5" />
  </joint>

</robot>
